Workbook
Name ByCategoryChartCategoryName: _xlfn.ANCHORARRAY('Chart Data'!$F$5)
Name ByCategoryChartMargin: _xlfn.ANCHORARRAY('Chart Data'!$G$5)
Name ByFridgeChartFridgeName: _xlfn.ANCHORARRAY('Chart Data'!$C$5)
Name ByFridgeChartMargin: _xlfn.ANCHORARRAY('Chart Data'!$D$5)
Name FormatDateYear: _xlfn.LAMBDA(_xlpm.Dates, TEXT(_xlpm.Dates, "mmmm yyyy"))
Name FrigolocoDiscountProvider: Settings!$C$5
Name MonthAndYearList: _xlfn.ANCHORARRAY('DV List'!$C$3)
Name MonthWiseLogisticsCost: _xlfn.ANCHORARRAY('Weekly Data'!$AG$5)
Name POSAndSoftwarePercentage: Settings!$C$3
Name RFIDTagAndTransactionFee: Settings!$C$4
Name WeeklyViewCateringFoodCost: 'Weekly View'!$F$4
Name WeeklyViewCateringTurnover: 'Weekly View'!$D$4
Name WeeklyViewLogisticsCost: 'Weekly View'!$G$4
Name WeeklyViewNumberOfDrops: 'Weekly View'!$H$4
Name WeeklyViewRemarks: 'Weekly View'!$J$4
Name WeeklyViewShowProgressCell: 'Weekly View'!$C$1
Name WeeklyViewTGTGTurnover: 'Weekly View'!$E$4
Name WeeklyViewUnsoldItems: 'Weekly View'!$I$4
Name WeeklyViewWeekNo: 'Weekly View'!$C$4
Name WeeklyViewYear: 'Weekly View'!$B$4
Name WeekStartDate: _xlfn.LAMBDA(_xlpm.WeekNo,_xlpm.Year,_xlfn.LET(_xlpm.\\LambdaName, "WeekStartDate", DATE(_xlpm.Year, 1, 1) - WEEKDAY(DATE(_xlpm.Year, 1, 1), 2) + 1 + (_xlpm.WeekNo - 1) * 7))

Sheet Settings
B2: Key | C2: Value | D2: Unit | E2: Comment
B3: POS & Software Percentage | C3: 0.09 | E3: Husky Fee on Sales
B4: RFID Tag & Transaction Fee | C4: 0.1 | D4: Per Item Sold | E4: We have RFID Tag on each product
B5: Frigoloco Discount Provider | C5: Frigo Loco Depot, Discount General | E5: Provider name in the discount part.
B9: TODO
B11: Take VAT off the turnover | C11: 0.06
B12: Create Monthly for 2026

Sheet Weekly View
C1: Tables updated successfully.
B3: Year | C3: Week No | D3: Busines Lunch CA | E3: TGTG CA | F3: Business Lunch Food Cost | G3: Logistics Cost | H3: # Of Drops | I3: Unsold Items | J3: Remarks
B4: 2026 | C4: 26 | E4: 55 | H4: 120 | I4: 0
C6: Start Date | D6: End Date | E6: In History?
C7: {=WeekStartDate(WeeklyViewWeekNo,WeeklyViewYear)} -> 46195 | D7: =C7+6 -> 46201 | E7: =NOT(ISNA(MATCH(C4,WeeklySummaryDataTable[Week No],0))) -> TRUE
B20: ="W" & C23&"-"&"W"&C31& " sales turnover, food margin and logistics" -> W18-W26 sales turnover, food margin and logistics | I20: ="Week " & WeeklyViewWeekNo & " Food Margin By Fridge" -> Week 26 Food Margin By Fridge | P20: ="Week " & WeeklyViewWeekNo & " Food Margin By Category" -> Week 26 Food Margin By Category
B22: Year | C22: Week No | D22: Logistics Cost | E22: Added Food Cost | F22: Sales Turnover | G22: Margin post logistics % | I22: Fridge Name | J22: Net Sale | K22: Food Cost | L22: Margin | M22: Margin% | P22: Category Name | Q22: Net Sale | R22: Food Cost | S22: Margin | T22: Margin %
B23: {=_xlfn.LET(_xlpm.WeekStartDate, C7, _xlpm.WeekOffsets, _xlfn.SEQUENCE(9, 1, -8, 1), _xlpm.TargetDates, _xlpm.WeekStartDate + _xlpm.WeekOffsets * 7, _xlfn.HSTACK(YEAR(_xlpm.TargetDates), _xlfn.ISOWEEKNUM(_xlpm.TargetDates)))} -> 2026 | C23: 18 | D23: {=_xlfn.MAP(_xlfn.CHOOSECOLS(_xlfn.ANCHORARRAY(B23), 1), _xlfn.CHOOSECOLS(_xlfn.ANCHORARRAY(B23), 2), _xlfn.LAMBDA(_xlpm.Year,_xlpm.WeekNo, _xlfn.XLOOKUP(1, (WeeklySummaryDataTable[Week No] = _xlpm.WeekNo) * (YEAR(WeeklySummaryDataTable[Start Date]) = _xlpm.Year), WeeklySummaryDataTable[Logistics Cost], 0)))} -> 1709 | E23: {=_xlfn.MAP(_xlfn.CHOOSECOLS(_xlfn.ANCHORARRAY(B23), 1), _xlfn.CHOOSECOLS(_xlfn.ANCHORARRAY(B23), 2), _xlfn.LAMBDA(_xlpm.Year,_xlpm.WeekNo, _xlfn.XLOOKUP(1, (WeeklySummaryDataTable[Week No] = _xlpm.WeekNo) * (YEAR(WeeklySummaryDataTable[Start Date]) = _xlpm.Year), WeeklySummaryDataTable[Added Food Cost], 0)))} -> 10551.3 | F23: {=_xlfn.MAP(_xlfn.CHOOSECOLS(_xlfn.ANCHORARRAY(B23), 1), _xlfn.CHOOSECOLS(_xlfn.ANCHORARRAY(B23), 2), _xlfn.LAMBDA(_xlpm.Year,_xlpm.WeekNo, _xlfn.XLOOKUP(1, (WeeklySummaryDataTable[Week No] = _xlpm.WeekNo) * (YEAR(WeeklySummaryDataTable[Start Date]) = _xlpm.Year), WeeklySummaryDataTable[Sales Turnover], 0)))} -> 13518.821 | G23: {=_xlfn.MAP(_xlfn.CHOOSECOLS(_xlfn.ANCHORARRAY(B23), 1), _xlfn.CHOOSECOLS(_xlfn.ANCHORARRAY(B23), 2), _xlfn.LAMBDA(_xlpm.Year,_xlpm.WeekNo, _xlfn.XLOOKUP(1, (WeeklySummaryDataTable[Week No] = _xlpm.WeekNo) * (YEAR(WeeklySummaryDataTable[Start Date]) = _xlpm.Year), WeeklySummaryDataTable[Net Margin %], 0)))} -> 0.0071988792 | I23: {=_xlfn.LET(_xlpm.SalesData, _xlfn._xlws.FILTER(_xlfn.HSTACK(ByFridgeWeeklySalesDataTable[Fridge Name], ByFridgeWeeklySalesDataTable[Net Sale]), (ByFridgeWeeklySalesDataTable[Week No] = WeeklyViewWeekNo) * (YEAR(ByFridgeWeeklySalesDataTable[Week Start Date]) = WeeklyViewYear)), _xlpm.FoodCostData, _xlfn._xlws.FILTER(_xlfn.HSTACK(ByFridgeWeeklyDispatchDataTable[Fridge Name], ByFridgeWeeklyDispatchDataTable[Foodcost Value]), (ByFridgeWeeklyDispatchDataTable[Week No] = WeeklyViewWeekNo) * (YEAR(ByFridgeWeeklyDispatchDataTable[Week Start Date]) = WeeklyViewYear)), _xlpm.StackedData, _xlfn.VSTACK(IFERROR(_xlpm.SalesData, ""), IFERROR(_xlpm.FoodCostData, "")), _xlpm.UniqueFridgeName, _xlfn.UNIQUE(_xlfn.CHOOSECOLS(_xlfn._xlws.FILTER(_xlpm.StackedData, _xlfn.CHOOSECOLS(_xlpm.StackedData, 1) <> ""), 1)), _xlpm.SalesByFridge, _xlfn.MAP(_xlpm.UniqueFridgeName, _xlfn.LAMBDA(_xlpm.FridgeName, IFERROR(_xlfn._xlws.FILTER(_xlfn.CHOOSECOLS(_xlpm.SalesData, 2), _xlfn.CHOOSECOLS(_xlpm.SalesData, 1) = _xlpm.FridgeName), 0))), _xlpm.FoodCost, _xlfn.MAP(_xlpm.UniqueFridgeName, _xlfn.LAMBDA(_xlpm.FridgeName, IFERROR(_xlfn.XLOOKUP(_xlpm.FridgeName, _xlfn.CHOOSECOLS(_xlpm.FoodCostData, 1), _xlfn.CHOOSECOLS(_xlpm.FoodCostData, 2), 0), 0))), _xlpm.Margin, _xlpm.SalesByFridge - _xlpm.FoodCost, _xlpm.MarginPercentage, IFERROR(_xlpm.Margin / _xlpm.SalesByFridge, 0), _xlpm.Sorted, _xlfn.SORTBY(_xlfn.HSTACK(_xlpm.UniqueFridgeName, _xlpm.SalesByFridge, _xlpm.FoodCost, _xlpm.Margin, _xlpm.MarginPercentage), _xlpm.Margin, 1), _xlpm.Result, _xlfn._xlws.FILTER(_xlpm.Sorted, _xlfn.CHOOSECOLS(_xlpm.Sorted, 1) <> 0), _xlpm.Result)} -> Allnex Freezer | J23: 283.88 | K23: 380.65 | L23: -96.77 | M23: -0.34088347 | P23: {=_xlfn.LET(_xlpm.SalesData, _xlfn._xlws.FILTER(_xlfn.HSTACK(ByCategoryWeeklySalesDataTable[Category Name], ByCategoryWeeklySalesDataTable[Net Sale]), (ByCategoryWeeklySalesDataTable[Week No] = WeeklyViewWeekNo) * (YEAR(ByCategoryWeeklySalesDataTable[Week Start Date]) = WeeklyViewYear)), _xlpm.FoodCostData, _xlfn._xlws.FILTER(_xlfn.HSTACK(ByCategoryWeeklyDispatchDataTable[Category Name], ByCategoryWeeklyDispatchDataTable[Foodcost Value]), (ByCategoryWeeklyDispatchDataTable[Week No] = WeeklyViewWeekNo) * (YEAR(ByCategoryWeeklyDispatchDataTable[Week Start Date]) = WeeklyViewYear)), _xlpm.StackedData, _xlfn.VSTACK(IFERROR(_xlpm.SalesData, ""), IFERROR(_xlpm.FoodCostData, "")), _xlpm.UniqueCategoryName, _xlfn.UNIQUE(_xlfn.CHOOSECOLS(_xlfn._xlws.FILTER(_xlpm.StackedData, NOT(ISNA(_xlfn.CHOOSECOLS(_xlpm.StackedData, 2)))), 1)), _xlpm.SalesByCategory, _xlfn.MAP(_xlpm.UniqueCategoryName, _xlfn.LAMBDA(_xlpm.CategoryName, IFERROR(_xlfn._xlws.FILTER(_xlfn.CHOOSECOLS(_xlpm.SalesData, 2), _xlfn.CHOOSECOLS(_xlpm.SalesData, 1) = _xlpm.CategoryName), 0))), _xlpm.FoodCost, _xlfn.MAP(_xlpm.UniqueCategoryName, _xlfn.LAMBDA(_xlpm.CategoryName, IFERROR(_xlfn.XLOOKUP(_xlpm.CategoryName, _xlfn.CHOOSECOLS(_xlpm.FoodCostData, 1), _xlfn.CHOOSECOLS(_xlpm.FoodCostData, 2), 0), 0))), _xlpm.Margin, _xlpm.SalesByCategory - _xlpm.FoodCost, _xlpm.MarginPercentage, IFERROR(_xlpm.Margin / _xlpm.SalesByCategory, 0), _xlpm.Sorted, _xlfn.SORTBY(_xlfn.HSTACK(_xlpm.UniqueCategoryName, _xlpm.SalesByCategory, _xlpm.FoodCost, _xlpm.Margin, _xlpm.MarginPercentage), _xlpm.Margin, 1), _xlpm.Sorted)} -> 10. Frozen Warm Dishes | Q23: 283.88 | R23: 380.65 | S23: -96.77 | T23: -0.34088347
B24: 2026 | C24: 19 | D24: 1728.72 | E24: 11043.59 | F24: 14729.009 | G24: 0.06280904 | I24: Spadel Brussels | J24: 125.58 | K24: 155.9 | L24: -30.32 | M24: -0.24143972 | P24: Unknown | Q24: 3.2 | R24: 0 | S24: 3.2 | T24: 1
B25: 2026 | C25: 20 | D25: 1514.2 | E25: 10473.69 | F25: 12398.028 | G25: -0.091487706 | I25: Lhoist Corbais | J25: 53.56 | K25: 81.67 | L25: -28.11 | M25: -0.52483196 | P25: 3. Warm Dishes Jar | Q25: 372.87 | R25: 227.3 | S25: 145.57 | T25: 0.39040416
B26: 2026 | C26: 21 | D26: 0 | E26: 0 | F26: 0 | G26: 0 | I26: Atelier rue du Cerf | J26: 117.48 | K26: 128.13 | L26: -10.65 | M26: -0.090653728 | P26: 4. Warm Dishes | Q26: 1938.6 | R26: 1602.13 | S26: 336.47 | T26: 0.1735634
B27: 2026 | C27: 22 | D27: 1583 | E27: 9993.46 | F27: 13073.66 | G27: 0.02766004 | I27: Velux | J27: 134.53 | K27: 141.01 | L27: -6.48 | M27: -0.048167695 | P27: 6. Snacks | Q27: 921.09 | R27: 534.78 | S27: 386.31 | T27: 0.41940527
B28: 2026 | C28: 23 | D28: 1983.33 | E28: 12099.23 | F28: 16621 | G28: 0.091500036 | I28: Brussels Airlines Vilvoorde | J28: 142.65 | K28: 143.2 | L28: -0.55 | M28: -0.0038555906 | P28: 8. Breakfast | Q28: 1442.95 | R28: 903 | S28: 539.95 | T28: 0.37419869
B29: 2026 | C29: 24 | D29: 1741 | E29: 12314.94 | F29: 16094.462 | G29: 0.032856516 | I29: Abbott Wavre | J29: 82.56 | K29: 71.24 | L29: 11.32 | M29: 0.1371124 | P29: 7. Drinks | Q29: 1155.95 | R29: 594.64 | S29: 561.31 | T29: 0.48558329
B30: 2026 | C30: 25 | D30: 1689 | E30: 0 | F30: 15332.038 | G30: 0.033876347 | I30: Brussels Airlines TFC | J30: 104.78 | K30: 88.52 | L30: 16.26 | M30: 0.15518229 | P30: 5. Desserts | Q30: 2801.86 | R30: 1922.15 | S30: 879.71 | T30: 0.31397357
B31: 2026 | C31: 26 | D31: 1711.6 | E31: 12267.45 | F31: 16903.538 | G31: 0.090223682 | I31: Brussels Airlines Airport | J31: 213.48 | K31: 196.76 | L31: 16.72 | M31: 0.078321154 | P31: 1. Cold Dishes | Q31: 3496.94 | R31: 2478.05 | S31: 1018.89 | T31: 0.29136617
I32: ABB Zaventem | J32: 177.09 | K32: 152.59 | L32: 24.5 | M32: 0.13834773 | P32: 2. Wraps & Sandwiches | Q32: 5500.41 | R32: 3596.64 | S32: 1903.77 | T32: 0.3461142
I33: Bank Degroof | J33: 130.52 | K33: 103.22 | L33: 27.3 | M33: 0.20916335 | P33: TOTAL | Q33: =SUM(Q23:Q32)/1.06 -> 16903.538 | R33: =SUM(R23:R32) -> 12239.34 | S33: =(SUM(S23:S32))-(SUM(Q23:Q32)*0.06) -> 4603.345 | T33: =S33/Q33 -> 0.27233027
I34: Engie Antwerpen | J34: 119.07 | K34: 78.36 | L34: 40.71 | M34: 0.34189972
I35: Lhoist Nivelles | J35: 171 | K35: 126.24 | L35: 44.76 | M35: 0.26175439
I36: PWC Ghent | J36: 167.81 | K36: 120.26 | L36: 47.55 | M36: 0.28335618
I37: Thermofisher Vilvoorde | J37: 118.05 | K37: 68.09 | L37: 49.96 | M37: 0.4232105
I38: Allianz Brussels | J38: 330.86 | K38: 253.37 | L38: 77.49 | M38: 0.23420782
I39: Engie Namur | J39: 295.12 | K39: 208.09 | L39: 87.03 | M39: 0.29489699
I40: Greenhouse Collection Links | J40: 338.56 | K40: 235.27 | L40: 103.29 | M40: 0.30508625
I41: Police Tubize | J41: 358.78 | K41: 255.49 | L41: 103.29 | M41: 0.2878923
I42: Interparking | J42: 289.1 | K42: 181.68 | L42: 107.42 | M42: 0.37156693
I43: Bia Group Overijse | J43: 347.05 | K43: 236.86 | L43: 110.19 | M43: 0.31750468
I44: Lhoist Limelette | J44: 257.57 | K44: 145.74 | L44: 111.83 | M44: 0.43417323
I45: GSV Huppertz Wilrijk | J45: 560.78 | K45: 410.42 | L45: 150.36 | M45: 0.26812654
... I63: RTBF Mediasquare 2e | J63: 1656.74 | K63: 1019.07 | L63: 637.67 | M63: 0.38489443
I66: TOTAL | J66: =SUM(J23:J64)/1.06 -> 16903.538 | K66: =SUM(K23:K64) -> 12239.34 | L66: =SUM(L23:L64)-(SUM(J23:J64)*0.06) -> 4603.345 | M66: =L66/J66 -> 0.27233027

Sheet Weekly Data
K1: =8869-M14 -> 8869
T2: MANUAL
E3: INCL VAT | H3: INCL VAT | I3: EX VAT | K3: From Wix/Manual Input | L3: Manual Input | M3: Comes from dispatch | N3: Manual/Wix | O3: Manual Input | P3: Manual Input | Q3: Manual Input | R3: Manual Input | S3: From Settings Sheet | U3: Calculated Fields | AF3: Month Wise Logistics Cost
B4: Week No | C4: Start Date | D4: End Date | E4: Total Sales | F4: Total Refund | G4: FrigoLoco Discount | H4: Customer Credit | I4: Sales Turnover | J4: # Of Fridge | K4: Catering Turnover | L4: TGTG Turnover | M4: Fridge Food Cost | N4: Added Food Cost | O4: Catering Food Cost | P4: Logistics Cost | Q4: # Of Drops | R4: Unsold Items | S4: Remarks | T4: POS & Software Percentage | U4: RFID Tags | V4: Per Fridge Turnover | W4: Food Margin In Euro | X4: Food Margin % | Y4: Food Margin for catering % | Z4: Logistic Cost Per Fridge | AA4: Logistic % | AB4: Unsold Item % | AC4: Net Margin | AD4: Net Margin % | AE4: Colonne1 | AG4: Month Name | AH4: Cost
B5: 34 | C5: 45887 | D5: 45893 | E5: 9171.81 | F5: 8.5 | G5: 144.22 | H5: 720.75 | I5: =(WeeklySummaryDataTable[[#This Row],[Total Sales]]+WeeklySummaryDataTable[[#This Row],[Customer Credit]]-WeeklySummaryDataTable[[#This Row],[Total Refund]])/1.06 -> 9324.5849 | J5: 31 | K5: 135 | L5: 55 | M5: =WeeklySummaryDataTable[[#This Row],[Added Food Cost]] -> 7090.91 | N5: {=IFERROR(SUM(_xlfn._xlws.FILTER(ByCategoryWeeklyAddedDataTable[Added Value],(ByCategoryWeeklyAddedDataTable[Week No]=WeeklySummaryDataTable[[#This Row],[Week No]])*(ByCategoryWeeklyAddedDataTable[Start Date]=WeeklySummaryDataTable[[#This Row],[Start Date]]))),0)} -> 7090.91 | O5: 100 | P5: 1572 | Q5: 120 | R5: 0 | T5: =WeeklySummaryDataTable[[#This Row],[Total Sales]]*Settings!$C$3 -> 825.4629 | U5: 0.1 | V5: =WeeklySummaryDataTable[[#This Row],[Sales Turnover]]/WeeklySummaryDataTable[[#This Row],['# Of Fridge]] -> 300.79306 | W5: =WeeklySummaryDataTable[[#This Row],[Sales Turnover]]-WeeklySummaryDataTable[[#This Row],[Fridge Food Cost]] -> 2233.6749 | X5: =WeeklySummaryDataTable[[#This Row],[Food Margin In Euro]]/WeeklySummaryDataTable[[#This Row],[Sales Turnover]] -> 0.23954685 | Y5: =IFERROR((WeeklySummaryDataTable[[#This Row],[Catering Turnover]]-WeeklySummaryDataTable[[#This Row],[Catering Food Cost]])/WeeklySummaryDataTable[[#This Row],[Catering Turnover]],0) -> 0.25925926 | Z5: =WeeklySummaryDataTable[[#This Row],[Logistics Cost]]/WeeklySummaryDataTable[[#This Row],['# Of Fridge]] -> 50.709677 | AA5: =IFERROR(WeeklySummaryDataTable[[#This Row],[Logistics Cost]]/WeeklySummaryDataTable[[#This Row],[Sales Turnover]],0) -> 0.16858659 | AB5: =IFERROR(WeeklySummaryDataTable[[#This Row],[Unsold Items]]/WeeklySummaryDataTable[[#This Row],[Sales Turnover]],0) -> 0 | AC5: =(WeeklySummaryDataTable[[#This Row],[Sales Turnover]]+WeeklySummaryDataTable[[#This Row],[Catering Turnover]]+WeeklySummaryDataTable[[#This Row],[TGTG Turnover]])-(WeeklySummaryDataTable[[#This Row],[Fridge Food Cost]]+WeeklySummaryDataTable[[#This Row],[Catering Food Cost]]+WeeklySummaryDataTable[[#This Row],[Logistics Cost]])-WeeklySummaryDataTable[[#This Row],[POS & Software Percentage]]-WeeklySummaryDataTable[[#This Row],[RFID Tags]] -> -73.887994 | AD5: =IFERROR(WeeklySummaryDataTable[[#This Row],[Net Margin]]/(WeeklySummaryDataTable[[#This Row],[Sales Turnover]]+WeeklySummaryDataTable[[#This Row],[Catering Turnover]]+WeeklySummaryDataTable[[#This Row],[TGTG Turnover]]),0) -> -0.0077657612 | AG5: {=_xlfn.LET( _xlpm.StartDates, WeeklySummaryDataTable[Start Date], _xlpm.LogisticsCost, WeeklySummaryDataTable[Logistics Cost], _xlpm.AllDates, _xlfn.DROP( _xlfn.REDUCE( "", _xlfn.SEQUENCE(ROWS(_xlpm.StartDates)), _xlfn.LAMBDA(_xlpm.a,_xlpm.c, _xlfn.LET( _xlpm.StartDate, INDEX(_xlpm.StartDates, _xlpm.c, 1), _xlpm.PerDayLogisticsCost, INDEX(_xlpm.LogisticsCost, _xlpm.c, 1) / 7, _xlpm.Curr, _xlfn.HSTACK(_xlfn.SEQUENCE(7, 1, _xlpm.StartDate), _xlfn.DROP(_xlfn.EXPAND("", 8, 1, _xlpm.PerDayLogisticsCost), 1)), _xlfn.VSTACK(_xlpm.a, _xlpm.Curr) ) ) ), 1 ), _xlpm.GroupedData, _xlfn.GROUPBY(FormatDateYear(_xlfn.CHOOSECOLS(_xlpm.AllDates, 1)), _xlfn.CHOOSECOLS(_xlpm.AllDates, 2), _xleta.SUM, 0, 0), _xlpm.GroupedData )} -> April 2026 | AH5: 7706.4657
B6: 35 | C6: 45894 | D6: 45900 | E6: 9401.42 | F6: 7.41 | G6: 135.24 | H6: 811.67 | I6: =(WeeklySummaryDataTable[[#This Row],[Total Sales]]+WeeklySummaryDataTable[[#This Row],[Customer Credit]]-WeeklySummaryDataTable[[#This Row],[Total Refund]])/1.06 -> 9628 | J6: 31 | L6: 0 | M6: =WeeklySummaryDataTable[[#This Row],[Added Food Cost]] -> 7621.21 | N6: {=IFERROR(SUM(_xlfn._xlws.FILTER(ByCategoryWeeklyAddedDataTable[Added Value],(ByCategoryWeeklyAddedDataTable[Week No]=WeeklySummaryDataTable[[#This Row],[Week No]])*(ByCategoryWeeklyAddedDataTable[Start Date]=WeeklySummaryDataTable[[#This Row],[Start Date]]))),0)} -> 7621.21 | P6: 1377 | Q6: 120 | R6: 0 | T6: =WeeklySummaryDataTable[[#This Row],[Total Sales]]*Settings!$C$3 -> 846.1278 | U6: 0.1 | V6: =WeeklySummaryDataTable[[#This Row],[Sales Turnover]]/WeeklySummaryDataTable[[#This Row],['# Of Fridge]] -> 310.58065 | W6: =WeeklySummaryDataTable[[#This Row],[Sales Turnover]]-WeeklySummaryDataTable[[#This Row],[Fridge Food Cost]] -> 2006.79 | X6: =WeeklySummaryDataTable[[#This Row],[Food Margin In Euro]]/WeeklySummaryDataTable[[#This Row],[Sales Turnover]] -> 0.2084327 | Y6: =IFERROR((WeeklySummaryDataTable[[#This Row],[Catering Turnover]]-WeeklySummaryDataTable[[#This Row],[Catering Food Cost]])/WeeklySummaryDataTable[[#This Row],[Catering Turnover]],0) -> 0 | Z6: =WeeklySummaryDataTable[[#This Row],[Logistics Cost]]/WeeklySummaryDataTable[[#This Row],['# Of Fridge]] -> 44.419355 | AA6: =IFERROR(WeeklySummaryDataTable[[#This Row],[Logistics Cost]]/WeeklySummaryDataTable[[#This Row],[Sales Turnover]],0) -> 0.14302036 | AB6: =IFERROR(WeeklySummaryDataTable[[#This Row],[Unsold Items]]/WeeklySummaryDataTable[[#This Row],[Sales Turnover]],0) -> 0 | AC6: =(WeeklySummaryDataTable[[#This Row],[Sales Turnover]]+WeeklySummaryDataTable[[#This Row],[Catering Turnover]]+WeeklySummaryDataTable[[#This Row],[TGTG Turnover]])-(WeeklySummaryDataTable[[#This Row],[Fridge Food Cost]]+WeeklySummaryDataTable[[#This Row],[Catering Food Cost]]+WeeklySummaryDataTable[[#This Row],[Logistics Cost]])-WeeklySummaryDataTable[[#This Row],[POS & Software Percentage]]-WeeklySummaryDataTable[[#This Row],[RFID Tags]] -> -216.4378 | AD6: =IFERROR(WeeklySummaryDataTable[[#This Row],[Net Margin]]/(WeeklySummaryDataTable[[#This Row],[Sales Turnover]]+WeeklySummaryDataTable[[#This Row],[Catering Turnover]]+WeeklySummaryDataTable[[#This Row],[TGTG Turnover]]),0) -> -0.022480037 | AG6: August 2025 | AH6: 2949
B7: 36 | C7: 45901 | D7: 45907 | E7: 10268.51 | F7: 31.74 | G7: 164.69 | H7: 810.23 | I7: =(WeeklySummaryDataTable[[#This Row],[Total Sales]]+WeeklySummaryDataTable[[#This Row],[Customer Credit]]-WeeklySummaryDataTable[[#This Row],[Total Refund]])/1.06 -> 10421.698 | J7: 32 | K7: 492 | L7: 0 | M7: =WeeklySummaryDataTable[[#This Row],[Added Food Cost]] -> 8024.38 | N7: {=IFERROR(SUM(_xlfn._xlws.FILTER(ByCategoryWeeklyAddedDataTable[Added Value],(ByCategoryWeeklyAddedDataTable[Week No]=WeeklySummaryDataTable[[#This Row],[Week No]])*(ByCategoryWeeklyAddedDataTable[Start Date]=WeeklySummaryDataTable[[#This Row],[Start Date]]))),0)} -> 8024.38 | O7: 298 | P7: 1598 | Q7: 120 | R7: 0 | T7: =WeeklySummaryDataTable[[#This Row],[Total Sales]]*Settings!$C$3 -> 924.1659 | U7: 0.1 | V7: =WeeklySummaryDataTable[[#This Row],[Sales Turnover]]/WeeklySummaryDataTable[[#This Row],['# Of Fridge]] -> 325.67807 | W7: =WeeklySummaryDataTable[[#This Row],[Sales Turnover]]-WeeklySummaryDataTable[[#This Row],[Fridge Food Cost]] -> 2397.3181 | X7: =WeeklySummaryDataTable[[#This Row],[Food Margin In Euro]]/WeeklySummaryDataTable[[#This Row],[Sales Turnover]] -> 0.23003143 | Y7: =IFERROR((WeeklySummaryDataTable[[#This Row],[Catering Turnover]]-WeeklySummaryDataTable[[#This Row],[Catering Food Cost]])/WeeklySummaryDataTable[[#This Row],[Catering Turnover]],0) -> 0.39430894 | Z7: =WeeklySummaryDataTable[[#This Row],[Logistics Cost]]/WeeklySummaryDataTable[[#This Row],['# Of Fridge]] -> 49.9375 | AA7: =IFERROR(WeeklySummaryDataTable[[#This Row],[Logistics Cost]]/WeeklySummaryDataTable[[#This Row],[Sales Turnover]],0) -> 0.15333394 | AB7: =IFERROR(WeeklySummaryDataTable[[#This Row],[Unsold Items]]/WeeklySummaryDataTable[[#This Row],[Sales Turnover]],0) -> 0 | AC7: =(WeeklySummaryDataTable[[#This Row],[Sales Turnover]]+WeeklySummaryDataTable[[#This Row],[Catering Turnover]]+WeeklySummaryDataTable[[#This Row],[TGTG Turnover]])-(WeeklySummaryDataTable[[#This Row],[Fridge Food Cost]]+WeeklySummaryDataTable[[#This Row],[Catering Food Cost]]+WeeklySummaryDataTable[[#This Row],[Logistics Cost]])-WeeklySummaryDataTable[[#This Row],[POS & Software Percentage]]-WeeklySummaryDataTable[[#This Row],[RFID Tags]] -> 69.052213 | AD7: =IFERROR(WeeklySummaryDataTable[[#This Row],[Net Margin]]/(WeeklySummaryDataTable[[#This Row],[Sales Turnover]]+WeeklySummaryDataTable[[#This Row],[Catering Turnover]]+WeeklySummaryDataTable[[#This Row],[TGTG Turnover]]),0) -> 0.0063271141 | AG7: December 2025 | AH7: 6201
B8: 37 | C8: 45908 | D8: 45914 | E8: 10672.49 | F8: 52.98 | G8: 192.55 | H8: 786.79 | I8: =(WeeklySummaryDataTable[[#This Row],[Total Sales]]+WeeklySummaryDataTable[[#This Row],[Customer Credit]]-WeeklySummaryDataTable[[#This Row],[Total Refund]])/1.06 -> 10760.66 | J8: 32 | K8: 378 | L8: 0 | M8: =WeeklySummaryDataTable[[#This Row],[Added Food Cost]] -> 8505.82 | N8: {=IFERROR(SUM(_xlfn._xlws.FILTER(ByCategoryWeeklyAddedDataTable[Added Value],(ByCategoryWeeklyAddedDataTable[Week No]=WeeklySummaryDataTable[[#This Row],[Week No]])*(ByCategoryWeeklyAddedDataTable[Start Date]=WeeklySummaryDataTable[[#This Row],[Start Date]]))),0)} -> 8505.82 | O8: 225 | P8: 1550 | Q8: 120 | R8: 0 | T8: =WeeklySummaryDataTable[[#This Row],[Total Sales]]*Settings!$C$3 -> 960.5241 | U8: 0.1 | V8: =WeeklySummaryDataTable[[#This Row],[Sales Turnover]]/WeeklySummaryDataTable[[#This Row],['# Of Fridge]] -> 336.27064 | W8: =WeeklySummaryDataTable[[#This Row],[Sales Turnover]]-WeeklySummaryDataTable[[#This Row],[Fridge Food Cost]] -> 2254.8404 | X8: =WeeklySummaryDataTable[[#This Row],[Food Margin In Euro]]/WeeklySummaryDataTable[[#This Row],[Sales Turnover]] -> 0.2095448 | Y8: =IFERROR((WeeklySummaryDataTable[[#This Row],[Catering Turnover]]-WeeklySummaryDataTable[[#This Row],[Catering Food Cost]])/WeeklySummaryDataTable[[#This Row],[Catering Turnover]],0) -> 0.4047619 | Z8: =WeeklySummaryDataTable[[#This Row],[Logistics Cost]]/WeeklySummaryDataTable[[#This Row],['# Of Fridge]] -> 48.4375 | AA8: =IFERROR(WeeklySummaryDataTable[[#This Row],[Logistics Cost]]/WeeklySummaryDataTable[[#This Row],[Sales Turnover]],0) -> 0.1440432 | AB8: =IFERROR(WeeklySummaryDataTable[[#This Row],[Unsold Items]]/WeeklySummaryDataTable[[#This Row],[Sales Turnover]],0) -> 0 | AC8: =(WeeklySummaryDataTable[[#This Row],[Sales Turnover]]+WeeklySummaryDataTable[[#This Row],[Catering Turnover]]+WeeklySummaryDataTable[[#This Row],[TGTG Turnover]])-(WeeklySummaryDataTable[[#This Row],[Fridge Food Cost]]+WeeklySummaryDataTable[[#This Row],[Catering Food Cost]]+WeeklySummaryDataTable[[#This Row],[Logistics Cost]])-WeeklySummaryDataTable[[#This Row],[POS & Software Percentage]]-WeeklySummaryDataTable[[#This Row],[RFID Tags]] -> -102.78372 | AD8: =IFERROR(WeeklySummaryDataTable[[#This Row],[Net Margin]]/(WeeklySummaryDataTable[[#This Row],[Sales Turnover]]+WeeklySummaryDataTable[[#This Row],[Catering Turnover]]+WeeklySummaryDataTable[[#This Row],[TGTG Turnover]]),0) -> -0.0092276557 | AG8: February 2026 | AH8: 6513.4514
B9: 38 | C9: 45915 | D9: 45921 | E9: 9878.48 | F9: 135.48 | G9: 170.42 | H9: 874.43 | I9: =(WeeklySummaryDataTable[[#This Row],[Total Sales]]+WeeklySummaryDataTable[[#This Row],[Customer Credit]]-WeeklySummaryDataTable[[#This Row],[Total Refund]])/1.06 -> 10016.443 | J9: 33 | K9: 575 | L9: 0 | M9: =WeeklySummaryDataTable[[#This Row],[Added Food Cost]] -> 8269.66 | N9: {=IFERROR(SUM(_xlfn._xlws.FILTER(ByCategoryWeeklyAddedDataTable[Added Value],(ByCategoryWeeklyAddedDataTable[Week No]=WeeklySummaryDataTable[[#This Row],[Week No]])*(ByCategoryWeeklyAddedDataTable[Start Date]=WeeklySummaryDataTable[[#This Row],[Start Date]]))),0)} -> 8269.66 | O9: 351 | P9: 1730 | Q9: 120 | R9: 0 | T9: =WeeklySummaryDataTable[[#This Row],[Total Sales]]*Settings!$C$3 -> 889.0632 | U9: 0.1 | V9: =WeeklySummaryDataTable[[#This Row],[Sales Turnover]]/WeeklySummaryDataTable[[#This Row],['# Of Fridge]] -> 303.52859 | W9: =WeeklySummaryDataTable[[#This Row],[Sales Turnover]]-WeeklySummaryDataTable[[#This Row],[Fridge Food Cost]] -> 1746.7834 | X9: =WeeklySummaryDataTable[[#This Row],[Food Margin In Euro]]/WeeklySummaryDataTable[[#This Row],[Sales Turnover]] -> 0.17439158 | Y9: =IFERROR((WeeklySummaryDataTable[[#This Row],[Catering Turnover]]-WeeklySummaryDataTable[[#This Row],[Catering Food Cost]])/WeeklySummaryDataTable[[#This Row],[Catering Turnover]],0) -> 0.38956522 | Z9: =WeeklySummaryDataTable[[#This Row],[Logistics Cost]]/WeeklySummaryDataTable[[#This Row],['# Of Fridge]] -> 52.424242 | AA9: =IFERROR(WeeklySummaryDataTable[[#This Row],[Logistics Cost]]/WeeklySummaryDataTable[[#This Row],[Sales Turnover]],0) -> 0.172716 | AB9: =IFERROR(WeeklySummaryDataTable[[#This Row],[Unsold Items]]/WeeklySummaryDataTable[[#This Row],[Sales Turnover]],0) -> 0 | AC9: =(WeeklySummaryDataTable[[#This Row],[Sales Turnover]]+WeeklySummaryDataTable[[#This Row],[Catering Turnover]]+WeeklySummaryDataTable[[#This Row],[TGTG Turnover]])-(WeeklySummaryDataTable[[#This Row],[Fridge Food Cost]]+WeeklySummaryDataTable[[#This Row],[Catering Food Cost]]+WeeklySummaryDataTable[[#This Row],[Logistics Cost]])-WeeklySummaryDataTable[[#This Row],[POS & Software Percentage]]-WeeklySummaryDataTable[[#This Row],[RFID Tags]] -> -648.3798 | AD9: =IFERROR(WeeklySummaryDataTable[[#This Row],[Net Margin]]/(WeeklySummaryDataTable[[#This Row],[Sales Turnover]]+WeeklySummaryDataTable[[#This Row],[Catering Turnover]]+WeeklySummaryDataTable[[#This Row],[TGTG Turnover]]),0) -> -0.061217322 | AG9: June 2026 | AH9: 7124.93
B10: 39 | C10: 45922 | D10: 45928 | E10: 10469.73 | F10: 19.39 | G10: 156.88 | H10: 698.13 | I10: =(WeeklySummaryDataTable[[#This Row],[Total Sales]]+WeeklySummaryDataTable[[#This Row],[Customer Credit]]-WeeklySummaryDataTable[[#This Row],[Total Refund]])/1.06 -> 10517.425 | J10: 33 | K10: 1043 | L10: 34 | M10: =WeeklySummaryDataTable[[#This Row],[Added Food Cost]] -> 8123.8 | N10: {=IFERROR(SUM(_xlfn._xlws.FILTER(ByCategoryWeeklyAddedDataTable[Added Value],(ByCategoryWeeklyAddedDataTable[Week No]=WeeklySummaryDataTable[[#This Row],[Week No]])*(ByCategoryWeeklyAddedDataTable[Start Date]=WeeklySummaryDataTable[[#This Row],[Start Date]]))),0)} -> 8123.8 | O10: =WeeklySummaryDataTable[[#This Row],[Catering Turnover]]-Q52 -> 1043 | P10: 1456 | Q10: 120 | R10: 0 | T10: =WeeklySummaryDataTable[[#This Row],[Total Sales]]*Settings!$C$3 -> 942.2757 | U10: 0.1 | V10: =WeeklySummaryDataTable[[#This Row],[Sales Turnover]]/WeeklySummaryDataTable[[#This Row],['# Of Fridge]] -> 318.70983 | W10: =WeeklySummaryDataTable[[#This Row],[Sales Turnover]]-WeeklySummaryDataTable[[#This Row],[Fridge Food Cost]] -> 2393.6245 | X10: =WeeklySummaryDataTable[[#This Row],[Food Margin In Euro]]/WeeklySummaryDataTable[[#This Row],[Sales Turnover]] -> 0.22758657 | Y10: =IFERROR((WeeklySummaryDataTable[[#This Row],[Catering Turnover]]-WeeklySummaryDataTable[[#This Row],[Catering Food Cost]])/WeeklySummaryDataTable[[#This Row],[Catering Turnover]],0) -> 0 | Z10: =WeeklySummaryDataTable[[#This Row],[Logistics Cost]]/WeeklySummaryDataTable[[#This Row],['# Of Fridge]] -> 44.121212 | AA10: =IFERROR(WeeklySummaryDataTable[[#This Row],[Logistics Cost]]/WeeklySummaryDataTable[[#This Row],[Sales Turnover]],0) -> 0.13843693 | AB10: =IFERROR(WeeklySummaryDataTable[[#This Row],[Unsold Items]]/WeeklySummaryDataTable[[#This Row],[Sales Turnover]],0) -> 0 | AC10: =(WeeklySummaryDataTable[[#This Row],[Sales Turnover]]+WeeklySummaryDataTable[[#This Row],[Catering Turnover]]+WeeklySummaryDataTable[[#This Row],[TGTG Turnover]])-(WeeklySummaryDataTable[[#This Row],[Fridge Food Cost]]+WeeklySummaryDataTable[[#This Row],[Catering Food Cost]]+WeeklySummaryDataTable[[#This Row],[Logistics Cost]])-WeeklySummaryDataTable[[#This Row],[POS & Software Percentage]]-WeeklySummaryDataTable[[#This Row],[RFID Tags]] -> 29.248828 | AD10: =IFERROR(WeeklySummaryDataTable[[#This Row],[Net Margin]]/(WeeklySummaryDataTable[[#This Row],[Sales Turnover]]+WeeklySummaryDataTable[[#This Row],[Catering Turnover]]+WeeklySummaryDataTable[[#This Row],[TGTG Turnover]]),0) -> 0.0025226632 | AG10: March 2026 | AH10: 7768.4943
B11: 40 | C11: 45929 | D11: 45935 | E11: 10458.71 | F11: 29.57 | G11: 158.94 | H11: 840.83 | I11: =(WeeklySummaryDataTable[[#This Row],[Total Sales]]+WeeklySummaryDataTable[[#This Row],[Customer Credit]]-WeeklySummaryDataTable[[#This Row],[Total Refund]])/1.06 -> 10632.047 | J11: 33 | K11: 441 | L11: 55 | M11: =WeeklySummaryDataTable[[#This Row],[Added Food Cost]] -> 8596.88 | N11: {=IFERROR(SUM(_xlfn._xlws.FILTER(ByCategoryWeeklyAddedDataTable[Added Value],(ByCategoryWeeklyAddedDataTable[Week No]=WeeklySummaryDataTable[[#This Row],[Week No]])*(ByCategoryWeeklyAddedDataTable[Start Date]=WeeklySummaryDataTable[[#This Row],[Start Date]]))),0)} -> 8596.88 | O11: =WeeklySummaryDataTable[[#This Row],[Catering Turnover]]-Q53 -> 283 | P11: 1527.56 | Q11: 120 | R11: 0 | S11: Friday Refill @Neuhaus | T11: =WeeklySummaryDataTable[[#This Row],[Total Sales]]*Settings!$C$3 -> 941.2839 | U11: 0.1 | V11: =WeeklySummaryDataTable[[#This Row],[Sales Turnover]]/WeeklySummaryDataTable[[#This Row],['# Of Fridge]] -> 322.18325 | W11: =WeeklySummaryDataTable[[#This Row],[Sales Turnover]]-WeeklySummaryDataTable[[#This Row],[Fridge Food Cost]] -> 2035.1672 | X11: =WeeklySummaryDataTable[[#This Row],[Food Margin In Euro]]/WeeklySummaryDataTable[[#This Row],[Sales Turnover]] -> 0.19141818 | Y11: =IFERROR((WeeklySummaryDataTable[[#This Row],[Catering Turnover]]-WeeklySummaryDataTable[[#This Row],[Catering Food Cost]])/WeeklySummaryDataTable[[#This Row],[Catering Turnover]],0) -> 0.35827664 | Z11: =WeeklySummaryDataTable[[#This Row],[Logistics Cost]]/WeeklySummaryDataTable[[#This Row],['# Of Fridge]] -> 46.289697 | AA11: =IFERROR(WeeklySummaryDataTable[[#This Row],[Logistics Cost]]/WeeklySummaryDataTable[[#This Row],[Sales Turnover]],0) -> 0.14367506 | AB11: =IFERROR(WeeklySummaryDataTable[[#This Row],[Unsold Items]]/WeeklySummaryDataTable[[#This Row],[Sales Turnover]],0) -> 0 | AC11: =(WeeklySummaryDataTable[[#This Row],[Sales Turnover]]+WeeklySummaryDataTable[[#This Row],[Catering Turnover]]+WeeklySummaryDataTable[[#This Row],[TGTG Turnover]])-(WeeklySummaryDataTable[[#This Row],[Fridge Food Cost]]+WeeklySummaryDataTable[[#This Row],[Catering Food Cost]]+WeeklySummaryDataTable[[#This Row],[Logistics Cost]])-WeeklySummaryDataTable[[#This Row],[POS & Software Percentage]]-WeeklySummaryDataTable[[#This Row],[RFID Tags]] -> -220.77673 | AD11: =IFERROR(WeeklySummaryDataTable[[#This Row],[Net Margin]]/(WeeklySummaryDataTable[[#This Row],[Sales Turnover]]+WeeklySummaryDataTable[[#This Row],[Catering Turnover]]+WeeklySummaryDataTable[[#This Row],[TGTG Turnover]]),0) -> -0.019839665 | AG11: May 2026 | AH11: 5558.3486
B12: 41 | C12: 45936 | D12: 45942 | E12: 10482.68 | F12: 18.12 | G12: 152.55 | H12: 776.65 | I12: =(WeeklySummaryDataTable[[#This Row],[Total Sales]]+WeeklySummaryDataTable[[#This Row],[Customer Credit]]-WeeklySummaryDataTable[[#This Row],[Total Refund]])/1.06 -> 10604.915 | J12: 34 | K12: 549 | L12: 55 | M12: =WeeklySummaryDataTable[[#This Row],[Added Food Cost]] -> 8385.28 | N12: {=IFERROR(SUM(_xlfn._xlws.FILTER(ByCategoryWeeklyAddedDataTable[Added Value],(ByCategoryWeeklyAddedDataTable[Week No]=WeeklySummaryDataTable[[#This Row],[Week No]])*(ByCategoryWeeklyAddedDataTable[Start Date]=WeeklySummaryDataTable[[#This Row],[Start Date]]))),0)} -> 8385.28 | O12: =WeeklySummaryDataTable[[#This Row],[Catering Turnover]]-Q54 -> 225 | P12: 1527.56 | Q12: 120 | R12: 0 | S12: Friday Refill @Neuhaus | T12: =WeeklySummaryDataTable[[#This Row],[Total Sales]]*Settings!$C$3 -> 943.4412 | U12: 0.1 | V12: =WeeklySummaryDataTable[[#This Row],[Sales Turnover]]/WeeklySummaryDataTable[[#This Row],['# Of Fridge]] -> 311.90927 | W12: =WeeklySummaryDataTable[[#This Row],[Sales Turnover]]-WeeklySummaryDataTable[[#This Row],[Fridge Food Cost]] -> 2219.6351 | X12: =WeeklySummaryDataTable[[#This Row],[Food Margin In Euro]]/WeeklySummaryDataTable[[#This Row],[Sales Turnover]] -> 0.20930249 | Y12: =IFERROR((WeeklySummaryDataTable[[#This Row],[Catering Turnover]]-WeeklySummaryDataTable[[#This Row],[Catering Food Cost]])/WeeklySummaryDataTable[[#This Row],[Catering Turnover]],0) -> 0.59016393 | Z12: =WeeklySummaryDataTable[[#This Row],[Logistics Cost]]/WeeklySummaryDataTable[[#This Row],['# Of Fridge]] -> 44.928235 | AA12: =IFERROR(WeeklySummaryDataTable[[#This Row],[Logistics Cost]]/WeeklySummaryDataTable[[#This Row],[Sales Turnover]],0) -> 0.14404264 | AB12: =IFERROR(WeeklySummaryDataTable[[#This Row],[Unsold Items]]/WeeklySummaryDataTable[[#This Row],[Sales Turnover]],0) -> 0 | AC12: =(WeeklySummaryDataTable[[#This Row],[Sales Turnover]]+WeeklySummaryDataTable[[#This Row],[Catering Turnover]]+WeeklySummaryDataTable[[#This Row],[TGTG Turnover]])-(WeeklySummaryDataTable[[#This Row],[Fridge Food Cost]]+WeeklySummaryDataTable[[#This Row],[Catering Food Cost]]+WeeklySummaryDataTable[[#This Row],[Logistics Cost]])-WeeklySummaryDataTable[[#This Row],[POS & Software Percentage]]-WeeklySummaryDataTable[[#This Row],[RFID Tags]] -> 127.53389 | AD12: =IFERROR(WeeklySummaryDataTable[[#This Row],[Net Margin]]/(WeeklySummaryDataTable[[#This Row],[Sales Turnover]]+WeeklySummaryDataTable[[#This Row],[Catering Turnover]]+WeeklySummaryDataTable[[#This Row],[TGTG Turnover]]),0) -> 0.011377898 | AG12: November 2025 | AH12: 6840.5714
B13: 42 | C13: 45943 | D13: 45949 | E13: 11672.22 | F13: 23.7 | G13: 284.18 | H13: 759.86 | I13: =(WeeklySummaryDataTable[[#This Row],[Total Sales]]+WeeklySummaryDataTable[[#This Row],[Customer Credit]]-WeeklySummaryDataTable[[#This Row],[Total Refund]])/1.06 -> 11706.019 | J13: 35 | K13: 668 | L13: 55 | M13: =WeeklySummaryDataTable[[#This Row],[Added Food Cost]] -> 9679.64 | N13: {=IFERROR(SUM(_xlfn._xlws.FILTER(ByCategoryWeeklyAddedDataTable[Added Value],(ByCategoryWeeklyAddedDataTable[Week No]=WeeklySummaryDataTable[[#This Row],[Week No]])*(ByCategoryWeeklyAddedDataTable[Start Date]=WeeklySummaryDataTable[[#This Row],[Start Date]]))),0)} -> 9679.64 | O13: =WeeklySummaryDataTable[[#This Row],[Catering Turnover]]-Q55 -> 429 | P13: 1768.75 | Q13: 120 | R13: 0 | T13: =WeeklySummaryDataTable[[#This Row],[Total Sales]]*Settings!$C$3 -> 1050.4998 | U13: 0.1 | V13: =WeeklySummaryDataTable[[#This Row],[Sales Turnover]]/WeeklySummaryDataTable[[#This Row],['# Of Fridge]] -> 334.45768 | W13: =WeeklySummaryDataTable[[#This Row],[Sales Turnover]]-WeeklySummaryDataTable[[#This Row],[Fridge Food Cost]] -> 2026.3789 | X13: =WeeklySummaryDataTable[[#This Row],[Food Margin In Euro]]/WeeklySummaryDataTable[[#This Row],[Sales Turnover]] -> 0.17310572 | Y13: =IFERROR((WeeklySummaryDataTable[[#This Row],[Catering Turnover]]-WeeklySummaryDataTable[[#This Row],[Catering Food Cost]])/WeeklySummaryDataTable[[#This Row],[Catering Turnover]],0) -> 0.35778443 | Z13: =WeeklySummaryDataTable[[#This Row],[Logistics Cost]]/WeeklySummaryDataTable[[#This Row],['# Of Fridge]] -> 50.535714 | AA13: =IFERROR(WeeklySummaryDataTable[[#This Row],[Logistics Cost]]/WeeklySummaryDataTable[[#This Row],[Sales Turnover]],0) -> 0.15109748 | AB13: =IFERROR(WeeklySummaryDataTable[[#This Row],[Unsold Items]]/WeeklySummaryDataTable[[#This Row],[Sales Turnover]],0) -> 0 | AC13: =(WeeklySummaryDataTable[[#This Row],[Sales Turnover]]+WeeklySummaryDataTable[[#This Row],[Catering Turnover]]+WeeklySummaryDataTable[[#This Row],[TGTG Turnover]])-(WeeklySummaryDataTable[[#This Row],[Fridge Food Cost]]+WeeklySummaryDataTable[[#This Row],[Catering Food Cost]]+WeeklySummaryDataTable[[#This Row],[Logistics Cost]])-WeeklySummaryDataTable[[#This Row],[POS & Software Percentage]]-WeeklySummaryDataTable[[#This Row],[RFID Tags]] -> -498.97093 | AD13: =IFERROR(WeeklySummaryDataTable[[#This Row],[Net Margin]]/(WeeklySummaryDataTable[[#This Row],[Sales Turnover]]+WeeklySummaryDataTable[[#This Row],[Catering Turnover]]+WeeklySummaryDataTable[[#This Row],[TGTG Turnover]]),0) -> -0.040145641 | AG13: October 2025 | AH13: 7362.6029
B14: 43 | C14: 45950 | D14: 45956 | E14: 12075.26 | F14: 16.59 | G14: 154.68 | H14: 731.63 | I14: =(WeeklySummaryDataTable[[#This Row],[Total Sales]]+WeeklySummaryDataTable[[#This Row],[Customer Credit]]-WeeklySummaryDataTable[[#This Row],[Total Refund]])/1.06 -> 12066.321 | J14: 35 | K14: 129 | L14: 55 | M14: {=IFERROR(SUM(_xlfn._xlws.FILTER(ByCategoryWeeklyDispatchDataTable[Foodcost Value],ByCategoryWeeklyDispatchDataTable[Week No]=WeeklySummaryDataTable[[#This Row],[Week No]])),0)} -> 0 | N14: {=IFERROR(SUM(_xlfn._xlws.FILTER(ByCategoryWeeklyAddedDataTable[Added Value],(ByCategoryWeeklyAddedDataTable[Week No]=WeeklySummaryDataTable[[#This Row],[Week No]])*(ByCategoryWeeklyAddedDataTable[Start Date]=WeeklySummaryDataTable[[#This Row],[Start Date]]))),0)} -> 9007.02 | O14: =129-48.3 -> 80.7 | P14: 1768.75 | Q14: 120 | R14: 0 | T14: =WeeklySummaryDataTable[[#This Row],[Total Sales]]*Settings!$C$3 -> 1086.7734 | U14: 0.1 | V14: =WeeklySummaryDataTable[[#This Row],[Sales Turnover]]/WeeklySummaryDataTable[[#This Row],['# Of Fridge]] -> 344.75202 | W14: =WeeklySummaryDataTable[[#This Row],[Sales Turnover]]-WeeklySummaryDataTable[[#This Row],[Fridge Food Cost]] -> 12066.321 | X14: =WeeklySummaryDataTable[[#This Row],[Food Margin In Euro]]/WeeklySummaryDataTable[[#This Row],[Sales Turnover]] -> 1 | Y14: =IFERROR((WeeklySummaryDataTable[[#This Row],[Catering Turnover]]-WeeklySummaryDataTable[[#This Row],[Catering Food Cost]])/WeeklySummaryDataTable[[#This Row],[Catering Turnover]],0) -> 0.3744186 | Z14: =WeeklySummaryDataTable[[#This Row],[Logistics Cost]]/WeeklySummaryDataTable[[#This Row],['# Of Fridge]] -> 50.535714 | AA14: =IFERROR(WeeklySummaryDataTable[[#This Row],[Logistics Cost]]/WeeklySummaryDataTable[[#This Row],[Sales Turnover]],0) -> 0.14658569 | AB14: =IFERROR(WeeklySummaryDataTable[[#This Row],[Unsold Items]]/WeeklySummaryDataTable[[#This Row],[Sales Turnover]],0) -> 0 | AC14: =(WeeklySummaryDataTable[[#This Row],[Sales Turnover]]+WeeklySummaryDataTable[[#This Row],[Catering Turnover]]+WeeklySummaryDataTable[[#This Row],[TGTG Turnover]])-(WeeklySummaryDataTable[[#This Row],[Fridge Food Cost]]+WeeklySummaryDataTable[[#This Row],[Catering Food Cost]]+WeeklySummaryDataTable[[#This Row],[Logistics Cost]])-WeeklySummaryDataTable[[#This Row],[POS & Software Percentage]]-WeeklySummaryDataTable[[#This Row],[RFID Tags]] -> 9313.9974 | AD14: =IFERROR(WeeklySummaryDataTable[[#This Row],[Net Margin]]/(WeeklySummaryDataTable[[#This Row],[Sales Turnover]]+WeeklySummaryDataTable[[#This Row],[Catering Turnover]]+WeeklySummaryDataTable[[#This Row],[TGTG Turnover]]),0) -> 0.76030641 | AG14: September 2025 | AH14: 6770.4457
B15: 44 | C15: 45957 | D15: 45963 | E15: 12093.57 | F15: 0 | G15: 203.7 | H15: 750.48 | I15: =(WeeklySummaryDataTable[[#This Row],[Total Sales]]+WeeklySummaryDataTable[[#This Row],[Customer Credit]]-WeeklySummaryDataTable[[#This Row],[Total Refund]])/1.06 -> 12117.028 | J15: 35 | K15: 288.4 | L15: 55 | M15: {=IFERROR(SUM(_xlfn._xlws.FILTER(ByCategoryWeeklyDispatchDataTable[Foodcost Value],ByCategoryWeeklyDispatchDataTable[Week No]=WeeklySummaryDataTable[[#This Row],[Week No]])),0)} -> 0 | N15: {=IFERROR(SUM(_xlfn._xlws.FILTER(ByCategoryWeeklyAddedDataTable[Added Value],(ByCategoryWeeklyAddedDataTable[Week No]=WeeklySummaryDataTable[[#This Row],[Week No]])*(ByCategoryWeeklyAddedDataTable[Start Date]=WeeklySummaryDataTable[[#This Row],[Start Date]]))),0)} -> 10395.01 | O15: 171.46 | P15: 1689 | Q15: 120 | R15: 0 | S15: Panne electricité chez Spadel - deucième semaine vacances toussaint | T15: =WeeklySummaryDataTable[[#This Row],[Total Sales]]*Settings!$C$3 -> 1088.4213 | U15: =U14 -> 0.1 | V15: =WeeklySummaryDataTable[[#This Row],[Sales Turnover]]/WeeklySummaryDataTable[[#This Row],['# Of Fridge]] -> 346.20081 | W15: =WeeklySummaryDataTable[[#This Row],[Sales Turnover]]-WeeklySummaryDataTable[[#This Row],[Fridge Food Cost]] -> 12117.028 | X15: =WeeklySummaryDataTable[[#This Row],[Food Margin In Euro]]/WeeklySummaryDataTable[[#This Row],[Sales Turnover]] -> 1 | Y15: =IFERROR((WeeklySummaryDataTable[[#This Row],[Catering Turnover]]-WeeklySummaryDataTable[[#This Row],[Catering Food Cost]])/WeeklySummaryDataTable[[#This Row],[Catering Turnover]],0) -> 0.4054785 | Z15: =WeeklySummaryDataTable[[#This Row],[Logistics Cost]]/WeeklySummaryDataTable[[#This Row],['# Of Fridge]] -> 48.257143 | AA15: =IFERROR(WeeklySummaryDataTable[[#This Row],[Logistics Cost]]/WeeklySummaryDataTable[[#This Row],[Sales Turnover]],0) -> 0.13939061 | AB15: =IFERROR(WeeklySummaryDataTable[[#This Row],[Unsold Items]]/WeeklySummaryDataTable[[#This Row],[Sales Turnover]],0) -> 0 | AC15: =(WeeklySummaryDataTable[[#This Row],[Sales Turnover]]+WeeklySummaryDataTable[[#This Row],[Catering Turnover]]+WeeklySummaryDataTable[[#This Row],[TGTG Turnover]])-(WeeklySummaryDataTable[[#This Row],[Fridge Food Cost]]+WeeklySummaryDataTable[[#This Row],[Catering Food Cost]]+WeeklySummaryDataTable[[#This Row],[Logistics Cost]])-WeeklySummaryDataTable[[#This Row],[POS & Software Percentage]]-WeeklySummaryDataTable[[#This Row],[RFID Tags]] -> 9511.447 | AD15: =IFERROR(WeeklySummaryDataTable[[#This Row],[Net Margin]]/(WeeklySummaryDataTable[[#This Row],[Sales Turnover]]+WeeklySummaryDataTable[[#This Row],[Catering Turnover]]+WeeklySummaryDataTable[[#This Row],[TGTG Turnover]]),0) -> 0.76333227
B16: 45 | C16: 45964 | D16: 45970 | E16: 13152.87 | F16: 44.64 | G16: 207.16 | H16: 812.08 | I16: =(WeeklySummaryDataTable[[#This Row],[Total Sales]]+WeeklySummaryDataTable[[#This Row],[Customer Credit]]-WeeklySummaryDataTable[[#This Row],[Total Refund]])/1.06 -> 13132.368 | J16: 35 | K16: 209 | L16: 55 | M16: {=IFERROR(SUM(_xlfn._xlws.FILTER(ByCategoryWeeklyDispatchDataTable[Foodcost Value],(ByCategoryWeeklyDispatchDataTable[Week No]=WeeklySummaryDataTable[[#This Row],[Week No]])*(ByCategoryWeeklyDispatchDataTable[Week Start Date]=WeeklySummaryDataTable[[#This Row],[Start Date]]))),0)} -> 0 | N16: {=IFERROR(SUM(_xlfn._xlws.FILTER(ByCategoryWeeklyAddedDataTable[Added Value],(ByCategoryWeeklyAddedDataTable[Week No]=WeeklySummaryDataTable[[#This Row],[Week No]])*(ByCategoryWeeklyAddedDataTable[Start Date]=WeeklySummaryDataTable[[#This Row],[Start Date]]))),0)} -> 10112.07 | O16: 137 | P16: 1811 | Q16: 120 | R16: 0 | T16: =WeeklySummaryDataTable[[#This Row],[Total Sales]]*Settings!$C$3 -> 1183.7583 | U16: 0.1 | V16: =WeeklySummaryDataTable[[#This Row],[Sales Turnover]]/WeeklySummaryDataTable[[#This Row],['# Of Fridge]] -> 375.21051 | W16: =WeeklySummaryDataTable[[#This Row],[Sales Turnover]]-WeeklySummaryDataTable[[#This Row],[Fridge Food Cost]] -> 13132.368 | X16: =WeeklySummaryDataTable[[#This Row],[Food Margin In Euro]]/WeeklySummaryDataTable[[#This Row],[Sales Turnover]] -> 1 | Y16: =IFERROR((WeeklySummaryDataTable[[#This Row],[Catering Turnover]]-WeeklySummaryDataTable[[#This Row],[Catering Food Cost]])/WeeklySummaryDataTable[[#This Row],[Catering Turnover]],0) -> 0.34449761 | Z16: =WeeklySummaryDataTable[[#This Row],[Logistics Cost]]/WeeklySummaryDataTable[[#This Row],['# Of Fridge]] -> 51.742857 | AA16: =IFERROR(WeeklySummaryDataTable[[#This Row],[Logistics Cost]]/WeeklySummaryDataTable[[#This Row],[Sales Turnover]],0) -> 0.13790354 | AB16: =IFERROR(WeeklySummaryDataTable[[#This Row],[Unsold Items]]/WeeklySummaryDataTable[[#This Row],[Sales Turnover]],0) -> 0 | AC16: =(WeeklySummaryDataTable[[#This Row],[Sales Turnover]]+WeeklySummaryDataTable[[#This Row],[Catering Turnover]]+WeeklySummaryDataTable[[#This Row],[TGTG Turnover]])-(WeeklySummaryDataTable[[#This Row],[Fridge Food Cost]]+WeeklySummaryDataTable[[#This Row],[Catering Food Cost]]+WeeklySummaryDataTable[[#This Row],[Logistics Cost]])-WeeklySummaryDataTable[[#This Row],[POS & Software Percentage]]-WeeklySummaryDataTable[[#This Row],[RFID Tags]] -> 10264.51 | AD16: =IFERROR(WeeklySummaryDataTable[[#This Row],[Net Margin]]/(WeeklySummaryDataTable[[#This Row],[Sales Turnover]]+WeeklySummaryDataTable[[#This Row],[Catering Turnover]]+WeeklySummaryDataTable[[#This Row],[TGTG Turnover]]),0) -> 0.76621586
B17: 46 | C17: 45971 | D17: 45977 | E17: 11038.47 | F17: 6.15 | G17: 187.55 | H17: 656.66 | I17: =(WeeklySummaryDataTable[[#This Row],[Total Sales]]+WeeklySummaryDataTable[[#This Row],[Customer Credit]]-WeeklySummaryDataTable[[#This Row],[Total Refund]])/1.06 -> 11027.34 | J17: 35 | K17: 570 | L17: 55 | M17: {=IFERROR(SUM(_xlfn._xlws.FILTER(ByCategoryWeeklyDispatchDataTable[Foodcost Value],(ByCategoryWeeklyDispatchDataTable[Week No]=WeeklySummaryDataTable[[#This Row],[Week No]])*(ByCategoryWeeklyDispatchDataTable[Week Start Date]=WeeklySummaryDataTable[[#This Row],[Start Date]]))),0)} -> 0 | N17: {=IFERROR(SUM(_xlfn._xlws.FILTER(ByCategoryWeeklyAddedDataTable[Added Value],(ByCategoryWeeklyAddedDataTable[Week No]=WeeklySummaryDataTable[[#This Row],[Week No]])*(ByCategoryWeeklyAddedDataTable[Start Date]=WeeklySummaryDataTable[[#This Row],[Start Date]]))),0)} -> 9032.725 | O17: 359 | P17: 1380 | Q17: 120 | R17: 0 | S17: Porte frigo RTBF Tombée 129€ à facturer | T17: =WeeklySummaryDataTable[[#This Row],[Total Sales]]*Settings!$C$3 -> 993.4623 | U17: 0.1 | V17: =WeeklySummaryDataTable[[#This Row],[Sales Turnover]]/WeeklySummaryDataTable[[#This Row],['# Of Fridge]] -> 315.06685 | W17: =WeeklySummaryDataTable[[#This Row],[Sales Turnover]]-WeeklySummaryDataTable[[#This Row],[Fridge Food Cost]] -> 11027.34 | X17: =WeeklySummaryDataTable[[#This Row],[Food Margin In Euro]]/WeeklySummaryDataTable[[#This Row],[Sales Turnover]] -> 1 | Y17: =IFERROR((WeeklySummaryDataTable[[#This Row],[Catering Turnover]]-WeeklySummaryDataTable[[#This Row],[Catering Food Cost]])/WeeklySummaryDataTable[[#This Row],[Catering Turnover]],0) -> 0.37017544 | Z17: =WeeklySummaryDataTable[[#This Row],[Logistics Cost]]/WeeklySummaryDataTable[[#This Row],['# Of Fridge]] -> 39.428571 | AA17: =IFERROR(WeeklySummaryDataTable[[#This Row],[Logistics Cost]]/WeeklySummaryDataTable[[#This Row],[Sales Turnover]],0) -> 0.12514351 | AB17: =IFERROR(WeeklySummaryDataTable[[#This Row],[Unsold Items]]/WeeklySummaryDataTable[[#This Row],[Sales Turnover]],0) -> 0 | AC17: =(WeeklySummaryDataTable[[#This Row],[Sales Turnover]]+WeeklySummaryDataTable[[#This Row],[Catering Turnover]]+WeeklySummaryDataTable[[#This Row],[TGTG Turnover]])-(WeeklySummaryDataTable[[#This Row],[Fridge Food Cost]]+WeeklySummaryDataTable[[#This Row],[Catering Food Cost]]+WeeklySummaryDataTable[[#This Row],[Logistics Cost]])-WeeklySummaryDataTable[[#This Row],[POS & Software Percentage]]-WeeklySummaryDataTable[[#This Row],[RFID Tags]] -> 8919.7773 | AD17: =IFERROR(WeeklySummaryDataTable[[#This Row],[Net Margin]]/(WeeklySummaryDataTable[[#This Row],[Sales Turnover]]+WeeklySummaryDataTable[[#This Row],[Catering Turnover]]+WeeklySummaryDataTable[[#This Row],[TGTG Turnover]]),0) -> 0.76549239
B18: 47 | C18: 45978 | D18: 45984 | E18: 14965.82 | F18: 44.07 | G18: 179.03 | H18: 904.3 | I18: =(WeeklySummaryDataTable[[#This Row],[Total Sales]]+WeeklySummaryDataTable[[#This Row],[Customer Credit]]-WeeklySummaryDataTable[[#This Row],[Total Refund]])/1.06 -> 14930.236 | J18: 37 | K18: 1304 | L18: 55 | M18: {=IFERROR(SUM(_xlfn._xlws.FILTER(ByCategoryWeeklyDispatchDataTable[Foodcost Value],(ByCategoryWeeklyDispatchDataTable[Week No]=WeeklySummaryDataTable[[#This Row],[Week No]])*(ByCategoryWeeklyDispatchDataTable[Week Start Date]=WeeklySummaryDataTable[[#This Row],[Start Date]]))),0)} -> 0 | N18: {=IFERROR(SUM(_xlfn._xlws.FILTER(ByCategoryWeeklyAddedDataTable[Added Value],(ByCategoryWeeklyAddedDataTable[Week No]=WeeklySummaryDataTable[[#This Row],[Week No]])*(ByCategoryWeeklyAddedDataTable[Start Date]=WeeklySummaryDataTable[[#This Row],[Start Date]]))),0)} -> 10837.072 | O18: 844 | P18: 1550 | Q18: 120 | R18: 0 | T18: =WeeklySummaryDataTable[[#This Row],[Total Sales]]*Settings!$C$3 -> 1346.9238 | U18: 0.1 | V18: =WeeklySummaryDataTable[[#This Row],[Sales Turnover]]/WeeklySummaryDataTable[[#This Row],['# Of Fridge]] -> 403.51989 | W18: =WeeklySummaryDataTable[[#This Row],[Sales Turnover]]-WeeklySummaryDataTable[[#This Row],[Fridge Food Cost]] -> 14930.236 | X18: =WeeklySummaryDataTable[[#This Row],[Food Margin In Euro]]/WeeklySummaryDataTable[[#This Row],[Sales Turnover]] -> 1 | Y18: =IFERROR((WeeklySummaryDataTable[[#This Row],[Catering Turnover]]-WeeklySummaryDataTable[[#This Row],[Catering Food Cost]])/WeeklySummaryDataTable[[#This Row],[Catering Turnover]],0) -> 0.35276074 | Z18: =WeeklySummaryDataTable[[#This Row],[Logistics Cost]]/WeeklySummaryDataTable[[#This Row],['# Of Fridge]] -> 41.891892 | AA18: =IFERROR(WeeklySummaryDataTable[[#This Row],[Logistics Cost]]/WeeklySummaryDataTable[[#This Row],[Sales Turnover]],0) -> 0.10381618 | AB18: =IFERROR(WeeklySummaryDataTable[[#This Row],[Unsold Items]]/WeeklySummaryDataTable[[#This Row],[Sales Turnover]],0) -> 0 | AC18: =(WeeklySummaryDataTable[[#This Row],[Sales Turnover]]+WeeklySummaryDataTable[[#This Row],[Catering Turnover]]+WeeklySummaryDataTable[[#This Row],[TGTG Turnover]])-(WeeklySummaryDataTable[[#This Row],[Fridge Food Cost]]+WeeklySummaryDataTable[[#This Row],[Catering Food Cost]]+WeeklySummaryDataTable[[#This Row],[Logistics Cost]])-WeeklySummaryDataTable[[#This Row],[POS & Software Percentage]]-WeeklySummaryDataTable[[#This Row],[RFID Tags]] -> 12548.212 | AD18: =IFERROR(WeeklySummaryDataTable[[#This Row],[Net Margin]]/(WeeklySummaryDataTable[[#This Row],[Sales Turnover]]+WeeklySummaryDataTable[[#This Row],[Catering Turnover]]+WeeklySummaryDataTable[[#This Row],[TGTG Turnover]]),0) -> 0.77033767
B19: 48 | C19: 45985 | D19: 45991 | E19: 13712.52 | F19: 37.88 | G19: 207.58 | H19: 859.54 | I19: =(WeeklySummaryDataTable[[#This Row],[Total Sales]]+WeeklySummaryDataTable[[#This Row],[Customer Credit]]-WeeklySummaryDataTable[[#This Row],[Total Refund]])/1.06 -> 13711.491 | J19: 37 | K19: 352 | L19: 55 | M19: {=IFERROR(SUM(_xlfn._xlws.FILTER(ByCategoryWeeklyDispatchDataTable[Foodcost Value],(ByCategoryWeeklyDispatchDataTable[Week No]=WeeklySummaryDataTable[[#This Row],[Week No]])*(ByCategoryWeeklyDispatchDataTable[Week Start Date]=WeeklySummaryDataTable[[#This Row],[Start Date]]))),0)} -> 0 | N19: {=IFERROR(SUM(_xlfn._xlws.FILTER(ByCategoryWeeklyAddedDataTable[Added Value],(ByCategoryWeeklyAddedDataTable[Week No]=WeeklySummaryDataTable[[#This Row],[Week No]])*(ByCategoryWeeklyAddedDataTable[Start Date]=WeeklySummaryDataTable[[#This Row],[Start Date]]))),0)} -> 10674.92 | O19: 212 | P19: 1617 | Q19: 120 | R19: 0 | T19: =WeeklySummaryDataTable[[#This Row],[Total Sales]]*Settings!$C$3 -> 1234.1268 | U19: 0.1 | V19: =WeeklySummaryDataTable[[#This Row],[Sales Turnover]]/WeeklySummaryDataTable[[#This Row],['# Of Fridge]] -> 370.58083 | W19: =WeeklySummaryDataTable[[#This Row],[Sales Turnover]]-WeeklySummaryDataTable[[#This Row],[Fridge Food Cost]] -> 13711.491 | X19: =WeeklySummaryDataTable[[#This Row],[Food Margin In Euro]]/WeeklySummaryDataTable[[#This Row],[Sales Turnover]] -> 1 | Y19: =IFERROR((WeeklySummaryDataTable[[#This Row],[Catering Turnover]]-WeeklySummaryDataTable[[#This Row],[Catering Food Cost]])/WeeklySummaryDataTable[[#This Row],[Catering Turnover]],0) -> 0.39772727 | Z19: =WeeklySummaryDataTable[[#This Row],[Logistics Cost]]/WeeklySummaryDataTable[[#This Row],['# Of Fridge]] -> 43.702703 | AA19: =IFERROR(WeeklySummaryDataTable[[#This Row],[Logistics Cost]]/WeeklySummaryDataTable[[#This Row],[Sales Turnover]],0) -> 0.11793029 | AB19: =IFERROR(WeeklySummaryDataTable[[#This Row],[Unsold Items]]/WeeklySummaryDataTable[[#This Row],[Sales Turnover]],0) -> 0 | AC19: =(WeeklySummaryDataTable[[#This Row],[Sales Turnover]]+WeeklySummaryDataTable[[#This Row],[Catering Turnover]]+WeeklySummaryDataTable[[#This Row],[TGTG Turnover]])-(WeeklySummaryDataTable[[#This Row],[Fridge Food Cost]]+WeeklySummaryDataTable[[#This Row],[Catering Food Cost]]+WeeklySummaryDataTable[[#This Row],[Logistics Cost]])-WeeklySummaryDataTable[[#This Row],[POS & Software Percentage]]-WeeklySummaryDataTable[[#This Row],[RFID Tags]] -> 11055.264 | AD19: =IFERROR(WeeklySummaryDataTable[[#This Row],[Net Margin]]/(WeeklySummaryDataTable[[#This Row],[Sales Turnover]]+WeeklySummaryDataTable[[#This Row],[Catering Turnover]]+WeeklySummaryDataTable[[#This Row],[TGTG Turnover]]),0) -> 0.7830344
B20: 49 | C20: 45992 | D20: 45998 | E20: 14803.99 | F20: 24.23 | G20: 262.56 | H20: 1017.83 | I20: =(WeeklySummaryDataTable[[#This Row],[Total Sales]]+WeeklySummaryDataTable[[#This Row],[Customer Credit]]-WeeklySummaryDataTable[[#This Row],[Total Refund]])/1.06 -> 14903.387 | J20: 37 | K20: 1008 | L20: 55 | M20: {=IFERROR(SUM(_xlfn._xlws.FILTER(ByCategoryWeeklyDispatchDataTable[Foodcost Value],(ByCategoryWeeklyDispatchDataTable[Week No]=WeeklySummaryDataTable[[#This Row],[Week No]])*(ByCategoryWeeklyDispatchDataTable[Week Start Date]=WeeklySummaryDataTable[[#This Row],[Start Date]]))),0)} -> 0 | N20: {=IFERROR(SUM(_xlfn._xlws.FILTER(ByCategoryWeeklyAddedDataTable[Added Value],(ByCategoryWeeklyAddedDataTable[Week No]=WeeklySummaryDataTable[[#This Row],[Week No]])*(ByCategoryWeeklyAddedDataTable[Start Date]=WeeklySummaryDataTable[[#This Row],[Start Date]]))),0)} -> 12033.34 | O20: 396.5 | P20: 1617 | Q20: 120 | R20: 0 | S20: 3 livreurs absent lundi, lancement 2 nouveau clients Zoetis et Thermo Vilvoorde | T20: =WeeklySummaryDataTable[[#This Row],[Total Sales]]*Settings!$C$3 -> 1332.3591 | U20: =WeeklySummaryDataTable[[#This Row],[Total Refund]]*Settings!$C$3 -> 2.1807 | V20: =WeeklySummaryDataTable[[#This Row],[Sales Turnover]]/WeeklySummaryDataTable[[#This Row],['# Of Fridge]] -> 402.79424 | W20: =WeeklySummaryDataTable[[#This Row],[Sales Turnover]]-WeeklySummaryDataTable[[#This Row],[Fridge Food Cost]] -> 14903.387 | X20: =WeeklySummaryDataTable[[#This Row],[Food Margin In Euro]]/WeeklySummaryDataTable[[#This Row],[Sales Turnover]] -> 1 | Y20: =IFERROR((WeeklySummaryDataTable[[#This Row],[Catering Turnover]]-WeeklySummaryDataTable[[#This Row],[Catering Food Cost]])/WeeklySummaryDataTable[[#This Row],[Catering Turnover]],0) -> 0.60664683 | Z20: =WeeklySummaryDataTable[[#This Row],[Logistics Cost]]/WeeklySummaryDataTable[[#This Row],['# Of Fridge]] -> 43.702703 | AA20: =IFERROR(WeeklySummaryDataTable[[#This Row],[Logistics Cost]]/WeeklySummaryDataTable[[#This Row],[Sales Turnover]],0) -> 0.10849883 | AB20: =IFERROR(WeeklySummaryDataTable[[#This Row],[Unsold Items]]/WeeklySummaryDataTable[[#This Row],[Sales Turnover]],0) -> 0 | AC20: =(WeeklySummaryDataTable[[#This Row],[Sales Turnover]]+WeeklySummaryDataTable[[#This Row],[Catering Turnover]]+WeeklySummaryDataTable[[#This Row],[TGTG Turnover]])-(WeeklySummaryDataTable[[#This Row],[Fridge Food Cost]]+WeeklySummaryDataTable[[#This Row],[Catering Food Cost]]+WeeklySummaryDataTable[[#This Row],[Logistics Cost]])-WeeklySummaryDataTable[[#This Row],[POS & Software Percentage]]-WeeklySummaryDataTable[[#This Row],[RFID Tags]] -> 12618.347 | AD20: =IFERROR(WeeklySummaryDataTable[[#This Row],[Net Margin]]/(WeeklySummaryDataTable[[#This Row],[Sales Turnover]]+WeeklySummaryDataTable[[#This Row],[Catering Turnover]]+WeeklySummaryDataTable[[#This Row],[TGTG Turnover]]),0) -> 0.79030698
B21: 50 | C21: 45999 | D21: 46005 | E21: 14189.5 | F21: 64.45 | G21: 302.1 | H21: 859.02 | I21: =(WeeklySummaryDataTable[[#This Row],[Total Sales]]+WeeklySummaryDataTable[[#This Row],[Customer Credit]]-WeeklySummaryDataTable[[#This Row],[Total Refund]])/1.06 -> 14135.915 | J21: 36 | K21: 375 | L21: 55 | M21: {=IFERROR(SUM(_xlfn._xlws.FILTER(ByCategoryWeeklyDispatchDataTable[Foodcost Value],(ByCategoryWeeklyDispatchDataTable[Week No]=WeeklySummaryDataTable[[#This Row],[Week No]])*(ByCategoryWeeklyDispatchDataTable[Week Start Date]=WeeklySummaryDataTable[[#This Row],[Start Date]]))),0)} -> 0 | N21: {=IFERROR(SUM(_xlfn._xlws.FILTER(ByCategoryWeeklyAddedDataTable[Added Value],(ByCategoryWeeklyAddedDataTable[Week No]=WeeklySummaryDataTable[[#This Row],[Week No]])*(ByCategoryWeeklyAddedDataTable[Start Date]=WeeklySummaryDataTable[[#This Row],[Start Date]]))),0)} -> 12059.72 | O21: 237 | P21: 1792 | Q21: 120 | R21: 0 | S21: Pas livraison Viangreo, remplacé par Colors Kitchen 2 proxideal, Livraison Zoetis apres midi et Namur pas livré | T21: =WeeklySummaryDataTable[[#This Row],[Total Sales]]*Settings!$C$3 -> 1277.055 | U21: 0.1 | V21: =WeeklySummaryDataTable[[#This Row],[Sales Turnover]]/WeeklySummaryDataTable[[#This Row],['# Of Fridge]] -> 392.66431 | W21: =WeeklySummaryDataTable[[#This Row],[Sales Turnover]]-WeeklySummaryDataTable[[#This Row],[Fridge Food Cost]] -> 14135.915 | X21: =WeeklySummaryDataTable[[#This Row],[Food Margin In Euro]]/WeeklySummaryDataTable[[#This Row],[Sales Turnover]] -> 1 | Y21: =IFERROR((WeeklySummaryDataTable[[#This Row],[Catering Turnover]]-WeeklySummaryDataTable[[#This Row],[Catering Food Cost]])/WeeklySummaryDataTable[[#This Row],[Catering Turnover]],0) -> 0.368 | Z21: =WeeklySummaryDataTable[[#This Row],[Logistics Cost]]/WeeklySummaryDataTable[[#This Row],['# Of Fridge]] -> 49.777778 | AA21: =IFERROR(WeeklySummaryDataTable[[#This Row],[Logistics Cost]]/WeeklySummaryDataTable[[#This Row],[Sales Turnover]],0) -> 0.1267693 | AB21: =IFERROR(WeeklySummaryDataTable[[#This Row],[Unsold Items]]/WeeklySummaryDataTable[[#This Row],[Sales Turnover]],0) -> 0 | AC21: =(WeeklySummaryDataTable[[#This Row],[Sales Turnover]]+WeeklySummaryDataTable[[#This Row],[Catering Turnover]]+WeeklySummaryDataTable[[#This Row],[TGTG Turnover]])-(WeeklySummaryDataTable[[#This Row],[Fridge Food Cost]]+WeeklySummaryDataTable[[#This Row],[Catering Food Cost]]+WeeklySummaryDataTable[[#This Row],[Logistics Cost]])-WeeklySummaryDataTable[[#This Row],[POS & Software Percentage]]-WeeklySummaryDataTable[[#This Row],[RFID Tags]] -> 11259.76 | AD21: =IFERROR(WeeklySummaryDataTable[[#This Row],[Net Margin]]/(WeeklySummaryDataTable[[#This Row],[Sales Turnover]]+WeeklySummaryDataTable[[#This Row],[Catering Turnover]]+WeeklySummaryDataTable[[#This Row],[TGTG Turnover]]),0) -> 0.77302113
